<?xml version="1.0" ?>
<robot name="ls_robot" xmlns:xacro="http://ros.org/wiki/xacro">
  <xacro:include filename="$(find ls_robot_description)/urdf/common_properties.urdf.xacro"/>
  <xacro:include filename="$(find ls_robot_description)/urdf/ls_robot_gazebo.urdf.xacro"/>

  <xacro:macro name="ls_robot">
    <link name="${ns}base_footprint"/>

    <joint name="${ns}base_joint" type="fixed">
      <origin xyz="0 0 0.0102" rpy="0 0 0" />
      <parent link="${ns}base_footprint"/>
      <child link="${ns}base_link" />
    </joint>
    <link name="${ns}base_link">
      <visual>
        <geometry>
        <cylinder length="0.10" radius="0.1"/>
        </geometry>
        <origin xyz="0.001 0 0.05199" rpy="0 0 0"/>
      </visual>
      <collision name="base">
        <geometry>
          <cylinder length="0.10" radius="0.1"/>
        </geometry>
        <origin xyz="0.0 0 0.05949" rpy="0 0 0"/>
      </collision>
      <inertial>
        <origin xyz="0.01 0 0"/>
        <mass value="0.4"/>
        <inertia ixx="0.019995" ixy="0.0" ixz="0.0"
                 iyy="0.019995" iyz="0.0"
                 izz="0.03675" />
      </inertial>
    </link>

    <joint name="${ns}wheel_left_joint" type="continuous">
      <parent link="${ns}base_link"/>
      <child link="${ns}wheel_left_link"/>
      <origin xyz="0.00 ${0.23/2} 0.0250" rpy="${-M_PI/2} 0 0"/>
      <axis xyz="0 0 1"/>
    </joint>

    <link name="${ns}wheel_left_link">
      <visual>
        <geometry>
          <mesh filename="package://ls_robot_description/meshes/wheel.dae"/>
        </geometry>
        <origin xyz="0 0 0" rpy="0 0 0"/>
      </visual>
      <collision>
        <geometry>
          <cylinder length="0.0206" radius="0.0352"/>
        </geometry>
        <origin rpy="0 0 0" xyz="0 0 0"/>
      </collision>
      <inertial>
        <mass value="0.01" />
        <origin xyz="0 0 0" />
        <inertia ixx="0.001" ixy="0.0" ixz="0.0"
                 iyy="0.001" iyz="0.0"
                 izz="0.001" />
      </inertial>
    </link>

    <joint name="${ns}wheel_right_joint" type="continuous">
      <parent link="${ns}base_link"/>
      <child link="${ns}wheel_right_link"/>
      <origin xyz="0.00 -${0.23/2} 0.0250" rpy="${-M_PI/2} 0 0"/>
      <axis xyz="0 0 1"/>
    </joint>

    <link name="${ns}wheel_right_link">
      <visual>
        <geometry>
          <mesh filename="package://ls_robot_description/meshes/wheel.dae"/>
        </geometry>
        <origin xyz="0 0 0" rpy="0 0 0"/>
      </visual>
      <collision>
        <geometry>
          <cylinder length="0.0206" radius="0.0350"/>
        </geometry>
        <origin rpy="0 0 0" xyz="0 0 0"/>
      </collision>
      <inertial>
        <mass value="0.01" />
        <origin xyz="0 0 0" />
        <inertia ixx="0.001" ixy="0.0" ixz="0.0"
                 iyy="0.001" iyz="0.0"
                 izz="0.001" />
      </inertial>
    </link>

    <joint name="${ns}caster_front_joint" type="fixed">
      <parent link="${ns}base_link"/>
      <child link="${ns}caster_front_link"/>
      <origin xyz="0.115 0.0 0.01" rpy="${-M_PI/2} 0 0"/>
    </joint>

    <link name="${ns}caster_front_link">
      <collision>
        <geometry>
          <cylinder length="0.0176" radius="0.017"/>
        </geometry>
        <origin rpy="0 0 0" xyz="0 0 0"/>
      </collision>
      <inertial>
        <mass value="0.01" />
        <origin xyz="0 0 0" />
        <inertia ixx="0.001" ixy="0.0" ixz="0.0"
                 iyy="0.001" iyz="0.0"
                 izz="0.001" />
      </inertial>
    </link>

    <joint name="${ns}caster_back_joint" type="fixed">
      <parent link="${ns}base_link"/>
      <child link="${ns}caster_back_link"/>
      <origin xyz="-0.135 0.0 0.01" rpy="${-M_PI/2} 0 0"/>
    </joint>

    <link name="${ns}caster_back_link">
      <collision>
        <geometry>
          <cylinder length="0.0176" radius="0.017"/>
        </geometry>
        <origin rpy="0 0 0" xyz="0 0 0"/>
      </collision>
      <inertial>
        <mass value="0.01" />
        <origin xyz="0 0 0" />
        <inertia ixx="0.001" ixy="0.0" ixz="0.0"
                 iyy="0.001" iyz="0.0"
                 izz="0.001" />
      </inertial>
    </link>

    <link name="${ns}laser_link">
      <visual>
        <geometry>
          <box size="0.03 0.03 0.05" />
        </geometry>
        <origin xyz="0 0 0" rpy="0 0 0"/>
      </visual>
      <collision>
        <geometry>
          <box size="0.03 0.03 0.05" />
        </geometry>
        <origin rpy="0 0 0" xyz="0 0 0"/>
      </collision>
      <inertial>
        <mass value="0.01" />
        <origin xyz="0 0 0" />
        <inertia ixx="0.001" ixy="0.0" ixz="0.0"
                 iyy="0.001" iyz="0.0"
                 izz="0.001" />
      </inertial>
    </link>

    <joint name="${ns}laser_joint" type="fixed">
      <parent link="${ns}base_link"/>
      <child link="${ns}laser_link"/>
      <origin xyz="0 0 0.155" rpy="0 0 0"/>
    </joint>

    <ls_robot_sim/>

</xacro:macro>
</robot>
